<?xml version="1.0" ?>
<!-- =================================================================================== -->
<!-- |    This document was autogenerated by xacro from /home/mk/catkin_ws/src/manipulator_description/urdf/manipulator.xacro | -->
<!-- |    EDITING THIS FILE BY HAND IS NOT RECOMMENDED                                 | -->
<!-- =================================================================================== -->
<robot name="manipulator">
    <material name="silver">
        <color rgba="0.700 0.700 0.700 1.000" />
    </material>
    <transmission name="joint1_tran">
        <type>transmission_interface/SimpleTransmission</type>
        <joint name="joint1">
            <hardwareInterface>hardware_interface/EffortJointInterface</hardwareInterface>
        </joint>
        <actuator name="joint1_actr">
            <hardwareInterface>hardware_interface/EffortJointInterface</hardwareInterface>
            <mechanicalReduction>1</mechanicalReduction>
        </actuator>
    </transmission>
    <transmission name="joint2_tran">
        <type>transmission_interface/SimpleTransmission</type>
        <joint name="joint2">
            <hardwareInterface>hardware_interface/EffortJointInterface</hardwareInterface>
        </joint>
        <actuator name="joint2_actr">
            <hardwareInterface>hardware_interface/EffortJointInterface</hardwareInterface>
            <mechanicalReduction>1</mechanicalReduction>
        </actuator>
    </transmission>
    <transmission name="joint3_tran">
        <type>transmission_interface/SimpleTransmission</type>
        <joint name="joint3">
            <hardwareInterface>hardware_interface/EffortJointInterface</hardwareInterface>
        </joint>
        <actuator name="joint3_actr">
            <hardwareInterface>hardware_interface/EffortJointInterface</hardwareInterface>
            <mechanicalReduction>1</mechanicalReduction>
        </actuator>
    </transmission>
    <transmission name="joint4_tran">
        <type>transmission_interface/SimpleTransmission</type>
        <joint name="joint4">
            <hardwareInterface>hardware_interface/EffortJointInterface</hardwareInterface>
        </joint>
        <actuator name="joint4_actr">
            <hardwareInterface>hardware_interface/EffortJointInterface</hardwareInterface>
            <mechanicalReduction>1</mechanicalReduction>
        </actuator>
    </transmission>
    <transmission name="joint5_tran">
        <type>transmission_interface/SimpleTransmission</type>
        <joint name="joint5">
            <hardwareInterface>hardware_interface/EffortJointInterface</hardwareInterface>
        </joint>
        <actuator name="joint5_actr">
            <hardwareInterface>hardware_interface/EffortJointInterface</hardwareInterface>
            <mechanicalReduction>1</mechanicalReduction>
        </actuator>
    </transmission>
    <transmission name="joint6_tran">
        <type>transmission_interface/SimpleTransmission</type>
        <joint name="joint6">
            <hardwareInterface>hardware_interface/EffortJointInterface</hardwareInterface>
        </joint>
        <actuator name="joint6_actr">
            <hardwareInterface>hardware_interface/EffortJointInterface</hardwareInterface>
            <mechanicalReduction>1</mechanicalReduction>
        </actuator>
    </transmission>
    <gazebo reference="base_link">
        <material>Gazebo/Silver</material>
        <mu1>0.0</mu1>
        <mu2>0.0</mu2>
        <selfCollide>true</selfCollide>
        <gravity>true</gravity>
        <plugin name="gazebo_ros_control" filename="libgazebo_ros_control.so">
            <robotNamespace>/</robotNamespace>
        </plugin>
    </gazebo>
    <gazebo reference="link1_1">
        <material>Gazebo/Silver</material>
        <mu1>0.0</mu1>
        <mu2>0.0</mu2>
        <gravity>false</gravity>
        <selfCollide>true</selfCollide>
    </gazebo>
    <gazebo reference="link2_1">
        <material>Gazebo/Silver</material>
        <mu1>0.0</mu1>
        <mu2>0.0</mu2>
        <gravity>false</gravity>
        <selfCollide>true</selfCollide>
    </gazebo>
    <gazebo reference="link3_1">
        <material>Gazebo/Silver</material>
        <mu1>0.0</mu1>
        <mu2>0.0</mu2>
        <gravity>false</gravity>
        <selfCollide>true</selfCollide>
    </gazebo>
    <gazebo reference="link4_1">
        <material>Gazebo/Silver</material>
        <mu1>0.0</mu1>
        <mu2>0.0</mu2>
        <gravity>false</gravity>
        <selfCollide>true</selfCollide>
    </gazebo>
    <gazebo reference="link5_1">
        <material>Gazebo/Silver</material>
        <mu1>0.0</mu1>
        <mu2>0.0</mu2>
        <gravity>false</gravity>
        <selfCollide>true</selfCollide>
    </gazebo>
    <gazebo reference="end_effector_1">
        <material>Gazebo/Silver</material>
        <mu1>0.0</mu1>
        <mu2>0.0</mu2>
        <gravity>false</gravity>
        <selfCollide>true</selfCollide>
    </gazebo>
    <gazebo>
        <plugin filename="libgazebo_ros_control.so" name="gazebo_ros_control" />
    </gazebo>
    <!-- 
<gazebo>
        <plugin name="gazebo_ros_control" filename="libgazebo_ros_control.so">
            <robotNamespace></robotNamespace>
            <robotSimType>gazebo_ros_control/DefaultRobotHWSim</robotSimType>
            <controlPeriod>0.001</controlPeriod>
            <legacyModeNS>false</legacyModeNS>
            <eStopTopic>emergency_stop</eStopTopic>
        </plugin>
    </gazebo> -->
    <link name="base_link">
        <inertial>
            <origin rpy="0 0 0" xyz="1.6995102266612555e-17 0.0 0.017670489394370294" />
            <mass value="4.200935832521195" />
            <inertia ixx="0.005311" ixy="0.0" ixz="0.0" iyy="0.005311" iyz="0.0" izz="0.009517" />
        </inertial>
        <visual>
            <origin rpy="0 0 0" xyz="0 0 0" />
            <geometry>
                <mesh filename="package://manipulator_description/meshes/base_link.stl" scale="0.001 0.001 0.001" />
            </geometry>
            <material name="silver" />
        </visual>
        <collision>
            <origin rpy="0 0 0" xyz="0 0 0" />
            <geometry>
                <mesh filename="package://manipulator_description/meshes/base_link.stl" scale="0.001 0.001 0.001" />
            </geometry>
        </collision>
    </link>
    <link name="link1_1">
        <inertial>
            <origin rpy="0 0 0" xyz="0.009094076659479818 1.7429587320305763e-12 0.05090592334052003" />
            <mass value="0.00001" />
            <inertia ixx="0.013347" ixy="-0.0" ixz="-0.001441" iyy="0.014236" iyz="0.0" izz="0.013347" />
        </inertial>
        <visual>
            <origin rpy="0 0 0" xyz="-0.0 -0.0 -0.04" />
            <geometry>
                <mesh filename="package://manipulator_description/meshes/link1_1.stl" scale="0.001 0.001 0.001" />
            </geometry>
            <material name="silver" />
        </visual>
        <collision>
            <origin rpy="0 0 0" xyz="-0.0 -0.0 -0.04" />
            <geometry>
                <mesh filename="package://manipulator_description/meshes/link1_1.stl" scale="0.001 0.001 0.001" />
            </geometry>
        </collision>
    </link>
    <link name="link2_1">
        <inertial>
            <origin rpy="0 0 0" xyz="0.05460983481316775 1.0340180735266833e-17 0.17500000000000002" />
            <mass value="0.00001" />
            <inertia ixx="0.5365" ixy="0.0" ixz="0.0" iyy="0.538828" iyz="-0.0" izz="0.038575" />
        </inertial>
        <visual>
            <origin rpy="0 0 0" xyz="-0.06 -0.0 -0.1" />
            <geometry>
                <mesh filename="package://manipulator_description/meshes/link2_1.stl" scale="0.001 0.001 0.001" />
            </geometry>
            <material name="silver" />
        </visual>
        <collision>
            <origin rpy="0 0 0" xyz="-0.06 -0.0 -0.1" />
            <geometry>
                <mesh filename="package://manipulator_description/meshes/link2_1.stl" scale="0.001 0.001 0.001" />
            </geometry>
        </collision>
    </link>
    <link name="link3_1">
        <inertial>
            <origin rpy="0 0 0" xyz="-0.039946462921333775 -8.280040038820753e-08 0.13748503978040622" />
            <mass value="0.00001" />
            <inertia ixx="0.234075" ixy="-0.0" ixz="0.000872" iyy="0.233879" iyz="-0.0" izz="0.0136" />
        </inertial>
        <visual>
            <origin rpy="0 0 0" xyz="-0.06 -0.0 -0.45" />
            <geometry>
                <mesh filename="package://manipulator_description/meshes/link3_1.stl" scale="0.001 0.001 0.001" />
            </geometry>
            <material name="silver" />
        </visual>
        <collision>
            <origin rpy="0 0 0" xyz="-0.06 -0.0 -0.45" />
            <geometry>
                <mesh filename="package://manipulator_description/meshes/link3_1.stl" scale="0.001 0.001 0.001" />
            </geometry>
        </collision>
    </link>
    <link name="link4_1">
        <inertial>
            <origin rpy="0 0 0" xyz="0.041464489207529376 1.9275193294255203e-17 0.00853551079246373" />
            <mass value="0.00001" />
            <inertia ixx="0.003484" ixy="0.0" ixz="-0.000413" iyy="0.003986" iyz="0.0" izz="0.003484" />
        </inertial>
        <visual>
            <origin rpy="0 0 0" xyz="-0.065 -0.0 -0.76" />
            <geometry>
                <mesh filename="package://manipulator_description/meshes/link4_1.stl" scale="0.001 0.001 0.001" />
            </geometry>
            <material name="silver" />
        </visual>
        <collision>
            <origin rpy="0 0 0" xyz="-0.065 -0.0 -0.76" />
            <geometry>
                <mesh filename="package://manipulator_description/meshes/link4_1.stl" scale="0.001 0.001 0.001" />
            </geometry>
        </collision>
    </link>
    <link name="link5_1">
        <inertial>
            <origin rpy="0 0 0" xyz="0.00853551079247053 1.927519329425524e-17 0.04146448920752921" />
            <mass value="0.00001" />
            <inertia ixx="0.003484" ixy="0.0" ixz="-0.000413" iyy="0.003986" iyz="0.0" izz="0.003484" />
        </inertial>
        <visual>
            <origin rpy="0 0 0" xyz="-0.115 -0.0 -0.81" />
            <geometry>
                <mesh filename="package://manipulator_description/meshes/link5_1.stl" scale="0.001 0.001 0.001" />
            </geometry>
            <material name="silver" />
        </visual>
        <collision>
            <origin rpy="0 0 0" xyz="-0.115 -0.0 -0.81" />
            <geometry>
                <mesh filename="package://manipulator_description/meshes/link5_1.stl" scale="0.001 0.001 0.001" />
            </geometry>
        </collision>
    </link>
    <link name="end_effector_1">
        <inertial>
            <origin rpy="0 0 0" xyz="0.10068741645979493 -0.002418752798366002 -0.021680440084669295" />
            <mass value="0.00001" />
            <inertia ixx="0.002644" ixy="0.000681" ixz="0.001348" iyy="0.007806" iyz="0.000218" izz="0.009109" />
        </inertial>
        <visual>
            <origin rpy="0 0 0" xyz="-0.165 -0.0 -0.86" />
            <geometry>
                <mesh filename="package://manipulator_description/meshes/end_effector_1.stl" scale="0.001 0.001 0.001" />
            </geometry>
            <material name="silver" />
        </visual>
        <collision>
            <origin rpy="0 0 0" xyz="-0.165 -0.0 -0.86" />
            <geometry>
                <mesh filename="package://manipulator_description/meshes/end_effector_1.stl" scale="0.001 0.001 0.001" />
            </geometry>
        </collision>
    </link>
    <link name="world" />
    <joint name="world_joint" type="fixed">
        <parent link="world" />
        <child link="base_link" />
        <origin rpy="0 0 0" xyz="0 0 0" />
    </joint>
    <joint name="joint1" type="revolute">
        <origin rpy="0 0 0" xyz="0.0 0.0 0.04" />
        <parent link="base_link" />
        <child link="link1_1" />
        <axis xyz="0.0 0.0 1.0" />
        <limit lower="-3.14159" upper="3.14159" effort="1000" velocity="2.0"/>
    </joint>
    <joint name="joint2" type="revolute">
        <origin rpy="0 0 0" xyz="0.06 0.0 0.06" />
        <parent link="link1_1" />
        <child link="link2_1" />
        <axis xyz="1.0 0.0 0.0" />
        <!-- <limit lower="-1.57" upper="1.57" effort="1000" velocity="2.0"/> -->
        <limit effort="1000.0" velocity="2.0" lower="-1.5708" upper="1.5708" />
    </joint>
    <joint name="joint3" type="revolute">
        <origin rpy="0 0 0" xyz="0.0 0.0 0.35" />
        <parent link="link2_1" />
        <child link="link3_1" />
        <axis xyz="-1.0 0.0 0.0" />
        <!-- <limit lower="-2.79253" upper="2.79253" effort="1000" velocity="2.0"/> -->
        <limit lower="-3.14159" upper="3.14159" effort="1000" velocity="2.0"/>
    </joint>
    <joint name="joint4" type="revolute">
        <origin rpy="0 0 0" xyz="0.005 0.0 0.31" />
        <parent link="link3_1" />
        <child link="link4_1" />
        <axis xyz="1.0 0.0 0.0" />
        <limit lower="-3.14159" upper="3.14159" effort="1000" velocity="2.0"/>
    </joint>
    <joint name="joint5" type="revolute">
        <origin rpy="0 0 0" xyz="0.05 0.0 0.05" />
        <parent link="link4_1" />
        <child link="link5_1" />
        <axis xyz="0.0 0.0 1.0" />
        <limit lower="-3.14159" upper="3.14159" effort="1000" velocity="2.0"/>
    </joint>
    <joint name="joint6" type="revolute">
        <origin rpy="0 0 0" xyz="0.05 0.0 0.05" />
        <parent link="link5_1" />
        <child link="end_effector_1" />
        <axis xyz="1.0 0.0 0.0" />
        <limit lower="-3.29867" upper="3.29867" effort="1000" velocity="2.0"/>
    </joint>
    <transmission name="joint1_transmission">
        <type>transmission_interface/SimpleTransmission</type>
        <!-- The EffortJointInterface works best with Gazebo using torques to actuate the joints -->
        <joint name="joint1">
            <hardwareInterface>hardware_interface/EffortJointInterface</hardwareInterface>
        </joint>
        <actuator name="joint1_motor">
            <hardwareInterface>hardware_interface/EffortJointInterface</hardwareInterface>
            <mechanicalReduction>1</mechanicalReduction>
        </actuator>
    </transmission>
    <transmission name="joint2_transmission">
        <type>transmission_interface/SimpleTransmission</type>
        <!-- The EffortJointInterface works best with Gazebo using torques to actuate the joints -->
        <joint name="joint2">
            <hardwareInterface>hardware_interface/EffortJointInterface</hardwareInterface>
        </joint>
        <actuator name="joint2_motor">
            <hardwareInterface>hardware_interface/EffortJointInterface</hardwareInterface>
            <mechanicalReduction>1</mechanicalReduction>
        </actuator>
    </transmission>
    <transmission name="joint3_transmission">
        <type>transmission_interface/SimpleTransmission</type>
        <!-- The EffortJointInterface works best with Gazebo using torques to actuate the joints -->
        <joint name="joint3">
            <hardwareInterface>hardware_interface/EffortJointInterface</hardwareInterface>
        </joint>
        <actuator name="joint3_motor">
            <hardwareInterface>hardware_interface/EffortJointInterface</hardwareInterface>
            <mechanicalReduction>1</mechanicalReduction>
        </actuator>
    </transmission>
    <transmission name="joint4_transmission">
        <type>transmission_interface/SimpleTransmission</type>
        <!-- The EffortJointInterface works best with Gazebo using torques to actuate the joints -->
        <joint name="joint4">
            <hardwareInterface>hardware_interface/EffortJointInterface</hardwareInterface>
        </joint>
        <actuator name="joint4_motor">
            <hardwareInterface>hardware_interface/EffortJointInterface</hardwareInterface>
            <mechanicalReduction>1</mechanicalReduction>
        </actuator>
    </transmission>
    <transmission name="joint5_transmission">
        <type>transmission_interface/SimpleTransmission</type>
        <!-- The EffortJointInterface works best with Gazebo using torques to actuate the joints -->
        <joint name="joint5">
            <hardwareInterface>hardware_interface/EffortJointInterface</hardwareInterface>
        </joint>
        <actuator name="joint5_motor">
            <hardwareInterface>hardware_interface/EffortJointInterface</hardwareInterface>
            <mechanicalReduction>1</mechanicalReduction>
        </actuator>
    </transmission>
    <transmission name="joint6_transmission">
        <type>transmission_interface/SimpleTransmission</type>
        <!-- The EffortJointInterface works best with Gazebo using torques to actuate the joints -->
        <joint name="joint6">
            <hardwareInterface>hardware_interface/EffortJointInterface</hardwareInterface>
        </joint>
        <actuator name="joint6_motor">
            <hardwareInterface>hardware_interface/EffortJointInterface</hardwareInterface>
            <mechanicalReduction>1</mechanicalReduction>
        </actuator>
    </transmission>

</robot>

